Workbook

Sheet Testplan
A1: ID | B1: Feature | C1: Stimulus | D1: Checker | E1: Coverage item | F1: Priority | G1: Status | H1: Notes
A2: RST001 | B2: After reset: tx=1, busy=0, rdy=0, data_out=0, TX and RX FSMs in IDLE. Must hold for a reset applied after traffic, not only at time 0. | C2: Hold rst >= 5 clks at sim start; re-apply rst after >= 1 completed frame. | D2: a_rst_values | E2: c_rst_after_traffic | F2: P1 | G2: Not started | H2: Sync reset, so the property uses |=> (new values visible next cycle). No 'disable iff (rst)' on this property. tx is the internal tx_rx wire: bind into UART or expose the pin.
A3: RST002 | B3: Reset during a TX frame aborts it: tx returns to 1, busy to 0, and the next frame sent after reset is correct. | C3: wr_en, then rst at a random point inside START, DATA or STOP; then send a fresh byte. | D3: a_rst_values; mon_tx (frame cut by rst is flagged 'aborted', not decoded); scb_tx drops the aborted byte | E3: c_rst_mid_tx; cp_tx_state_at_rst (bins START, DATA, STOP) | F3: P1 | G3: Not started | H3: mon_tx must treat a frame cut by rst as aborted, not as a protocol error.
A4: RST003 | B4: Reset during an RX frame: no rdy for the interrupted byte; the next complete frame is received correctly. | C4: drv_rx sends a frame; assert rst at a random point in START, DATA_OUT or STOP; idle the line for one frame time; send a good frame. | D4: scb_rx: no rdy for the interrupted byte; next byte matches | E4: cp_rx_state_at_rst (bins START, DATA_OUT, STOP) | F4: P2 | G4: Not started | H4: Spec decision: after a mid-frame reset the line still carries the rest of the old frame, so a 0 data bit looks like a start bit and RX may emit one junk byte. Either idle the line for a full frame before checking, or let scb_rx tolerate one junk byte. Needs drv_rx.
A5: RST004 | B5: Reset released while the rx line is low: no valid byte is produced while the line stays low. | C5: Hold rx low, assert then release rst, keep rx low for >= 3 frame times. | D5: scb_rx: rdy never rises during the low period | E5: c_rst_release_rx_low | F5: P3 | G5: Not started | H5: Needs drv_rx. Same checker as RXE004 (break), different reset timing.
A6: RST005 | B6: No X/Z on tx, busy, rdy or data_out once reset has been applied. | C6: Any test; checking starts at the first reset release. | D6: a_no_x (ADD SVA: !$isunknown({tx,busy,rdy,data_out})) | E6: c_no_x (vacuity) | F6: P1 | G6: Not started | H6: Outputs may legitimately be X before the first reset, so do not check then.
A7: BRG001 | B7: tx_tick is a one-cycle pulse exactly every clk_freq/baud_rate clocks (5208 at 50 MHz / 9600). | C7: Run >= 20 ticks after reset with default parameters; repeat per config in PAR001. | D7: a_tx_tick_period | E7: c_tx_tick_pair (tx_tick ##CLKS_PER_BIT tx_tick) - ADD | F7: P1 | G7: Not started | H7: CLKS_PER_BIT must match the integer division in baud_rate_generator.sv.
A8: BRG002 | B8: rx_tick is a one-cycle pulse every clk_freq/(16*baud_rate) clocks (325 at default), about 16 rx_ticks per bit. | C8: Run >= 100 rx_ticks after reset; repeat per config in PAR001. | D8: a_rx_tick_period (ADD SVA) | E8: c_rx_tick_pair - ADD | F8: P1 | G8: Not started | H8: 16 x 325 = 5200 clocks vs TX 5208: 0.15% mismatch at default. See Param_Calc for other configs.
A9: TXF001 | B9: Frame format: idle high, 1 start bit (0), 8 data bits LSB first, 1 stop bit (1), no parity. | C9: Directed bytes 0x00, 0xFF, 0x55, 0xAA, 0x01, 0x80, 0xA5 plus random bytes, one at a time with idle gaps. | D9: mon_tx independently decodes the tx line; decoded byte == data_in (scb_tx) | E9: cg_tx_data.cp_data (0x00, 0xFF, 0x55, 0xAA, 0x01, 0x80, walking-1, walking-0, other) | F9: P1 | G9: Not started | H9: Do not use RX as the decoder: loopback hides bit-order bugs. 0x01 and 0x80 catch MSB/LSB order errors only with an independent monitor.
A10: TXF002 | B10: Every bit (start, 8 data, stop) lasts exactly CLKS_PER_BIT clocks; the start bit begins on a tx_tick. | C10: Any frame; measure transitions in clocks. | D10: mon_tx bit-width check == CLKS_PER_BIT; a_tx_changes_on_tick | E10: c_tx_changed (vacuity) | F10: P1 | G10: Not started | H10: Measure against a bit-time grid anchored on the start-bit falling edge. A stop bit followed by idle can only be checked as >= 1 bit period.
A11: TXF003 | B11: tx idles high whenever busy=0, including after reset and between frames. | C11: Idle >= 2 frame times; after each frame; after reset. | D11: a_tx_idle_high | E11: c_tx_idle_high (vacuity) | F11: P1 | G11: Not started
A12: TXF004 | B12: Start bit begins on the next tx_tick after an accepted wr_en: latency 1 to CLKS_PER_BIT clocks (up to one bit period), including wr_en landing in the same cycle as a tx_tick. | C12: Issue wr_en at randomised phases relative to tx_tick, including the tick cycle and the cycles either side. | D12: a_start_latency (ADD SVA: (wr_en && !busy) |-> ##[1:CLKS_PER_BIT+1] !tx) | E12: cp_wr_phase (tick-1, tick, tick+1, early, mid, late in the tick period) | F12: P2 | G12: Not started | H12: IDLE ignores tx_tick, so wr_en in the tick cycle waits a full period - worth hitting on purpose. Bound has +1 slack; tighten after the first run.
A13: TXI001 | B13: wr_en while busy is dropped silently: the current frame is unaffected and no second frame is queued. | C13: Pulse wr_en with a different data_in at random times in START, DATA and STOP. | D13: scb_tx (only the first byte appears); mon_tx | E13: c_wr_en_while_busy; cp_wr_en_state (START, DATA, STOP) | F13: P1 | G13: Not started | H13: No busy-write error flag exists - document as accepted behaviour.
A14: TXI002 | B14: data_in is latched when wr_en is accepted; changing data_in afterwards does not alter the frame. | C14: Drive data_in = X with wr_en, change it to ~X on the next cycle and keep changing it during the frame. | D14: scb_tx / mon_tx: frame decodes to X | E14: cp_data_in_change_after_wr (hit) | F14: P1 | G14: Not started
A15: TXI003 | B15: Back-to-back: wr_en on the first cycle busy is low starts the next frame after exactly one full stop-bit period; no data lost. | C15: After each busy fall, re-issue wr_en immediately; >= 100 frames. | D15: mon_tx (stop-to-start gap == CLKS_PER_BIT); scb_tx | E15: c_wr_en_at_busy_fall (hit count >= 100) | F15: P1 | G15: Not started | H15: busy falls when the stop bit begins. The stop bit is a full period only because START waits for the next tick; this test confirms that.
A16: TXI004 | B16: wr_en held high continuously: TX sends frames back-to-back, re-latching data_in at each IDLE cycle. | C16: Hold wr_en high for >= 5 frames; change data_in between frames. | D16: scb_tx; mon_tx (one stop-bit period between frames) | E16: cp_wr_en_held (>= 3 consecutive frames) | F16: P2 | G16: Not started | H16: Spec decision: is continuous retrigger intended? Write the answer down either way.
A17: TXI005 | B17: busy rises the cycle after an accepted wr_en and falls when the stop bit begins. | C17: Any frame. | D17: a_busy_after_wr_en; mon_tx (busy fall coincides with stop-bit start) | E17: c_busy_after_wr_en (vacuity) | F17: P1 | G17: Not started
A18: RXF001 | B18: RX receives a correct 8N1 frame: data_out == transmitted byte, rdy rises once per frame. | C18: drv_rx sends directed and random bytes at nominal bit period (5208 clks) with idle gaps. | D18: scb_rx: data_out compared when rdy rises | E18: cg_rx_data.cp_data (same bins as cg_tx_data) | F18: P1 | G18: Not started | H18: Needs drv_rx and the exposed rx pin.
A19: RXF002 | B19: RX samples at mid-bit: start bit checked 8 rx_ticks after detection, then one sample every 16 rx_ticks (data bits and stop bit). | C19: Any frame. | D19: a_rx_sample_spacing (ADD SVA, bound into receiver_block using state/sample/index) | E19: cp_rx_index (0..7); cp_rx_sample_max (7 in START, 15 in DATA_OUT/STOP) | F19: P1 | G19: Not started | H19: Internal-signal assertion. The sample point is up to one rx_tick (1/16 bit) late because detection is tick-granular.
A20: RXF003 | B20: Frame is received correctly for every alignment of the start edge relative to rx_tick. | C20: drv_rx delays the start edge by 0..324 clks (sweep plus random). | D20: scb_rx | E20: cp_rx_edge_phase (>= 8 bins across 0..324) | F20: P1 | G20: Not started | H20: The practical sampling-correctness test. rx passes through a 2-FF synchronizer, so this also shows the 2-clock input latency has no effect.
A21: RXF004 | B21: Back-to-back frames with zero idle gap: start bit immediately after the stop bit; all received. | C21: drv_rx sends >= 100 frames with no gap, then with 1, 2 and 10-bit gaps. | D21: scb_rx | E21: cp_idle_gap (0, 1 bit, 2 bits, long) | F21: P1 | G21: Not started | H21: RX leaves STOP at mid-stop-bit, which gives about half a bit of slack for the next start edge.
A22: RXF005 | B22: Constant-line patterns: 0x00 (9 low bits incl. start), 0xFF (data looks like idle), alternating 0x55/0xAA - all received correctly. | C22: drv_rx sends each pattern singly and repeated back-to-back (e.g. 10x 0x00, 10x 0xFF). | D22: scb_rx | E22: cg_rx_data.cp_data bins 0x00, 0xFF, 0x55, 0xAA; cp_repeat (same byte >= 5x in a row) | F22: P1 | G22: Not started | H22: 0x00 checks RX counts bit periods instead of waiting for edges; 0xFF after the start bit is indistinguishable from idle.
A23: RXF006 | B23: Idle line (rx=1) for a long time: rdy never rises and RX stays in IDLE. | C23: Hold rx high >= 3 frame times after reset and between frames. | D23: a_rdy_only_in_stop (ADD SVA: rdy rises only after RX state STOP) | E23: c_rx_idle_long (rx high >= 3 frame times) | F23: P2 | G23: Not started
A24: RXI001 | B24: rdy stays high until rdy_clr, and data_out is held stable meanwhile. | C24: Receive a byte; delay rdy_clr by 1 clk, half a frame, one frame. | D24: a_rdy_holds; a_data_out_with_rdy | E24: cp_rdy_hold_time (1 clk, < 1 frame, >= 1 frame) | F24: P1 | G24: Not started | H24: A hold of >= 1 frame without a new byte needs an idle line afterwards.
A25: RXI002 | B25: rdy_clr clears rdy on the next cycle (a single-cycle pulse is enough). | C25: 1-cycle rdy_clr pulse while rdy=1 and no frame completing. | D25: a_rdy_clr_clears (ADD SVA: (rdy_clr && rdy && !completing) |=> !rdy) | E25: c_rdy_clr_pulse - ADD | F25: P1 | G25: Not started | H25: 'completing' = RX in STOP with sample==15 and rx_tick; take it from the receiver_block internals.
A26: RXI003 | B26: rdy_clr and a new byte completing in the same cycle: rdy ends up 1 (set wins over clear). | C26: Directed: time rdy_clr to the cycle the RX STOP state completes (align using internal state/sample). | D26: scb_rx: rdy stays 1 and data_out == new byte | E26: c_rdy_clr_collision | F26: P2 | G26: Not started | H26: Matches the RTL: rdy<=1 comes after rdy<=0 in the same always_ff. The existing cover only hits the case where rdy was already 1.
A27: RXI004 | B27: Overrun: a new frame completes while rdy is still 1. data_out is overwritten with the newest byte; no overrun flag. | C27: Receive 2+ frames without rdy_clr. | D27: scb_rx: data_out == newest byte (older byte lost) | E27: c_overrun | F27: P2 | G27: Not started | H27: Design limitation: no overrun flag. State it in the spec so it is not read as a miss.
A28: RXE001 | B28: Framing error (stop bit = 0): frame dropped - no rdy, data_out unchanged. | C28: drv_rx sends frames with stop=0 and random data; then an idle-high gap of >= 1 frame and a good frame. | D28: scb_rx (no rdy, data_out unchanged); a_rdy_only_in_stop | E28: cp_stop_val (0, 1); FSM002 arc STOP->IDLE with rx_s=0 | F28: P2 | G28: Not started | H28: No error flag. RX returns to IDLE at mid-stop with the line still low, so it re-detects a false start; record what happens on the following frame. Needs drv_rx.
A29: RXE002 | B29: Short glitch on an idle line (shorter than about half a bit) is rejected: START -> IDLE at sample 7, no rdy. | C29: Pulse rx low for w clks, w in {1, 2, 10, 100, 325, 1000, 2000, 2500}; idle high otherwise. | D29: scb_rx (no byte) | E29: cp_glitch_width (< 1 rx_tick, 1-4, 5-7, >= 8 rx_ticks); FSM002 arc START->IDLE | F29: P2 | G29: Not started | H29: Glitches narrower than one rx_tick may be missed entirely depending on alignment; either outcome passes. Needs drv_rx.
A30: RXE003 | B30: Characterise the glitch width at which a glitch is accepted as a start bit; expected result is a spurious 0xFF byte. | C30: Sweep glitch width from about 0.4 to 1.6 bit in 1/16-bit steps. | D30: scb_rx logs the threshold and the resulting byte (characterisation, not pass/fail) | E30: cp_glitch_width (extended bins up to 1.6 bit) | F30: P3 | G30: Not started | H30: A glitch still low at the mid-bit check looks like a real start; if it ends before the first data sample the byte is 0xFF with a valid stop. Record the threshold in the spec.
A31: RXE004 | B31: Break (rx held low >= 3 frame times): no rdy fires while the line is low. | C31: Hold rx low for 1, 2, 3+ frame times, then return high and send a good frame. | D31: scb_rx: no rdy during the break | E31: cp_break_len (1, 2, 3+ frames) | F31: P2 | G31: Not started | H31: RX keeps restarting during a break (each framing error leads to a new start). After release it can be mid pseudo-frame and emit one spurious byte - there is no break detection. Flush or tolerate one byte after release and document it.
A32: RXE005 | B32: Noise on a single sample: a flipped rx level at the mid-bit sample corrupts that bit (single-sample design, no majority vote). | C32: Flip rx for >= 1 rx_tick centred on the sample point of data bit k, k = 0..7. | D32: scb_rx expects bit k flipped (known limitation), or waive | E32: cp_noise_bit (0..7) | F32: P3 | G32: Not started | H32: Expected behaviour of this design. Either mark Waived with this reason, or add a 3-sample majority vote to the RTL and flip the expectation.
A33: BDT001 | B33: RX tolerates a transmitter bit-period offset of up to +/-2% from nominal. | C33: drv_rx bit period = round(5208 x (1 + offset)) clks for offset in {-2%, -1%, 0, +1%, +2%}; >= 20 random bytes each, random start-edge phase. | D33: scb_rx | E33: cp_baud_offset (-2..+2 % bins) | F33: P1 | G33: Not started | H33: Zero offset = 5208 clks (the TX period). RX's own period is 16 x 325 = 5200, so its true zero point is 0.15% lower.
A34: BDT002 | B34: Find the offset at which RX first fails; must pass through +/-3%. | C34: Offsets -6% to +6% in 1% steps; >= 50 random bytes each. | D34: scb_rx; log first failing offset in each direction | E34: cp_baud_offset (-6..+6 % bins) | F34: P2 | G34: Not started | H34: Hand estimate: failures start around +/-4 to 5% (the stop bit, sampled 9.5 bit times after the start edge, is the limit). Not simulated - record the measured limit in the spec.
A35: PAR001 | B35: Frame correctness over a parameter sweep of clk_freq and baud_rate. | C35: Run the supported configs from Param_Calc: (50M, 9600), (50M, 115200), (50M, 312500), (100M, 115200), (25M, 9600); smoke test plus E2E001 on each. | D35: mon_tx, scb_tx, scb_rx, SVA with CLKS_PER_BIT bound per config | E35: cp_cfg (one bin per config) | F35: P2 | G35: Not started | H35: Param_Calc shows the TX vs RX period mismatch per config. 312500 baud is 160 clks/bit - handy for long regressions.
... A37: E2E001 | B37: Loopback random traffic: every byte arrives once, in order, with the correct value. | C37: >= 1000 random bytes, random idle gaps (0 to 3 frame times), rdy_clr latency 1 to 20 clks. | D37: scb (in-order compare of TX queue vs RX data_out) | E37: cg_e2e (cp_data x cp_idle_gap) | F37: P1 | G37: Not started | H37: Keep rdy_clr latency well under one frame so overrun does not occur here (overrun is RXI004). 1000 frames at 9600 baud is about 52M clocks - use a faster baud config for long runs.
A38: E2E002 | B38: Directed data patterns end-to-end: 0x00, 0xFF, 0x55, 0xAA, 0x01, 0x80, walking 1 and walking 0, each repeated 10x. | C38: Directed sequence through wr_en, loopback to data_out. | D38: scb | E38: cg_tx_data.cp_data and cg_rx_data.cp_data - all bins hit | F38: P1 | G38: Not started
A39: E2E003 | B39: Consecutive frames in loopback with zero gap: >= 100 frames with wr_en re-issued on every busy fall. | C39: wr_en on the first cycle busy is low, random data. | D39: scb; a_busy_after_wr_en | E39: c_wr_en_at_busy_fall (hit count >= 100) | F39: P1 | G39: Not started | H39: System-level version of TXI003 (this one also checks that RX keeps up).
A40: E2E004 | B40: Reset in the middle of loopback traffic: system recovers and the first frame after reset (plus idle) is received correctly. | C40: Random rst during traffic; idle for one frame; send a frame; repeat. | D40: scb (flushed on rst); a_rst_values | E40: c_rst_mid_tx; cp_rx_state_at_rst | F40: P2 | G40: Not started | H40: Expect the same junk-byte question as RST003 - idle the line before checking.
A41: E2E005 | B41: Full duplex: a TX frame and an independently driven RX frame in flight at the same time; both correct. | C41: Start a TX frame and a drv_rx frame with random relative offset, different data. | D41: scb_tx / mon_tx and scb_rx | E41: cp_duplex_overlap (TX starts during RX START, DATA, STOP; and the reverse) | F41: P2 | G41: Not started | H41: Needs the exposed rx pin. TX and RX share one baud generator, so they cannot drift against each other here.
...

Sheet Summary
A1: UART verification plan - summary
A3: Total plan rows | B3: =COUNTA(Testplan!$A$2:$A$200) -> 44
A4: Pass rate (excluding waived) | B4: =IFERROR(COUNTIF(Testplan!$G$2:$G$200,"Pass")/(B3-COUNTIF(Testplan!$G$2:$G$200,"Waived")),0) -> 0
A5: Rows with an SVA still to add | B5: =COUNTIF(Testplan!$D$2:$D$200,"*ADD SVA*") -> 9
A7: Status by priority
A8: Status | B8: P1 | C8: P2 | D8: P3 | E8: Total
A9: Not started | B9: =COUNTIFS(Testplan!$G$2:$G$200,$A9,Testplan!$F$2:$F$200,B$8) -> 25 | C9: =COUNTIFS(Testplan!$G$2:$G$200,$A9,Testplan!$F$2:$F$200,C$8) -> 15 | D9: =COUNTIFS(Testplan!$G$2:$G$200,$A9,Testplan!$F$2:$F$200,D$8) -> 4 | E9: =SUM(B9:D9) -> 44
A10: In progress | B10: =COUNTIFS(Testplan!$G$2:$G$200,$A10,Testplan!$F$2:$F$200,B$8) -> 0 | C10: =COUNTIFS(Testplan!$G$2:$G$200,$A10,Testplan!$F$2:$F$200,C$8) -> 0 | D10: =COUNTIFS(Testplan!$G$2:$G$200,$A10,Testplan!$F$2:$F$200,D$8) -> 0 | E10: =SUM(B10:D10) -> 0
A11: Pass | B11: =COUNTIFS(Testplan!$G$2:$G$200,$A11,Testplan!$F$2:$F$200,B$8) -> 0 | C11: =COUNTIFS(Testplan!$G$2:$G$200,$A11,Testplan!$F$2:$F$200,C$8) -> 0 | D11: =COUNTIFS(Testplan!$G$2:$G$200,$A11,Testplan!$F$2:$F$200,D$8) -> 0 | E11: =SUM(B11:D11) -> 0
A12: Fail | B12: =COUNTIFS(Testplan!$G$2:$G$200,$A12,Testplan!$F$2:$F$200,B$8) -> 0 | C12: =COUNTIFS(Testplan!$G$2:$G$200,$A12,Testplan!$F$2:$F$200,C$8) -> 0 | D12: =COUNTIFS(Testplan!$G$2:$G$200,$A12,Testplan!$F$2:$F$200,D$8) -> 0 | E12: =SUM(B12:D12) -> 0
A13: Blocked | B13: =COUNTIFS(Testplan!$G$2:$G$200,$A13,Testplan!$F$2:$F$200,B$8) -> 0 | C13: =COUNTIFS(Testplan!$G$2:$G$200,$A13,Testplan!$F$2:$F$200,C$8) -> 0 | D13: =COUNTIFS(Testplan!$G$2:$G$200,$A13,Testplan!$F$2:$F$200,D$8) -> 0 | E13: =SUM(B13:D13) -> 0
A14: Waived | B14: =COUNTIFS(Testplan!$G$2:$G$200,$A14,Testplan!$F$2:$F$200,B$8) -> 0 | C14: =COUNTIFS(Testplan!$G$2:$G$200,$A14,Testplan!$F$2:$F$200,C$8) -> 0 | D14: =COUNTIFS(Testplan!$G$2:$G$200,$A14,Testplan!$F$2:$F$200,D$8) -> 0 | E14: =SUM(B14:D14) -> 0
A15: Total | B15: =SUM(B9:B14) -> 25 | C15: =SUM(C9:C14) -> 15 | D15: =SUM(D9:D14) -> 4 | E15: =SUM(E9:E14) -> 44
A16: Rows with unrecognised status/priority | B16: =B3-E15 -> 0
A18: By area
A19: Area | B19: ID prefix | C19: Total | D19: Pass | E19: % Pass
A20: Reset | B20: RST | C20: =COUNTIF(Testplan!$A$2:$A$200,B20&"*") -> 5 | D20: =COUNTIFS(Testplan!$A$2:$A$200,B20&"*",Testplan!$G$2:$G$200,"Pass") -> 0 | E20: =IFERROR(D20/C20,0) -> 0
A21: Baud generator | B21: BRG | C21: =COUNTIF(Testplan!$A$2:$A$200,B21&"*") -> 2 | D21: =COUNTIFS(Testplan!$A$2:$A$200,B21&"*",Testplan!$G$2:$G$200,"Pass") -> 0 | E21: =IFERROR(D21/C21,0) -> 0
A22: TX frame format and timing | B22: TXF | C22: =COUNTIF(Testplan!$A$2:$A$200,B22&"*") -> 4 | D22: =COUNTIFS(Testplan!$A$2:$A$200,B22&"*",Testplan!$G$2:$G$200,"Pass") -> 0 | E22: =IFERROR(D22/C22,0) -> 0
A23: TX host interface | B23: TXI | C23: =COUNTIF(Testplan!$A$2:$A$200,B23&"*") -> 5 | D23: =COUNTIFS(Testplan!$A$2:$A$200,B23&"*",Testplan!$G$2:$G$200,"Pass") -> 0 | E23: =IFERROR(D23/C23,0) -> 0
A24: RX reception and sampling | B24: RXF | C24: =COUNTIF(Testplan!$A$2:$A$200,B24&"*") -> 6 | D24: =COUNTIFS(Testplan!$A$2:$A$200,B24&"*",Testplan!$G$2:$G$200,"Pass") -> 0 | E24: =IFERROR(D24/C24,0) -> 0
A25: RX host interface | B25: RXI | C25: =COUNTIF(Testplan!$A$2:$A$200,B25&"*") -> 4 | D25: =COUNTIFS(Testplan!$A$2:$A$200,B25&"*",Testplan!$G$2:$G$200,"Pass") -> 0 | E25: =IFERROR(D25/C25,0) -> 0
A26: RX errors and robustness | B26: RXE | C26: =COUNTIF(Testplan!$A$2:$A$200,B26&"*") -> 5 | D26: =COUNTIFS(Testplan!$A$2:$A$200,B26&"*",Testplan!$G$2:$G$200,"Pass") -> 0 | E26: =IFERROR(D26/C26,0) -> 0
A27: Baud tolerance | B27: BDT | C27: =COUNTIF(Testplan!$A$2:$A$200,B27&"*") -> 2 | D27: =COUNTIFS(Testplan!$A$2:$A$200,B27&"*",Testplan!$G$2:$G$200,"Pass") -> 0 | E27: =IFERROR(D27/C27,0) -> 0
A28: Parameters | B28: PAR | C28: =COUNTIF(Testplan!$A$2:$A$200,B28&"*") -> 2 | D28: =COUNTIFS(Testplan!$A$2:$A$200,B28&"*",Testplan!$G$2:$G$200,"Pass") -> 0 | E28: =IFERROR(D28/C28,0) -> 0
A29: End-to-end | B29: E2E | C29: =COUNTIF(Testplan!$A$2:$A$200,B29&"*") -> 5 | D29: =COUNTIFS(Testplan!$A$2:$A$200,B29&"*",Testplan!$G$2:$G$200,"Pass") -> 0 | E29: =IFERROR(D29/C29,0) -> 0
A30: FSM and counter coverage | B30: FSM | C30: =COUNTIF(Testplan!$A$2:$A$200,B30&"*") -> 3 | D30: =COUNTIFS(Testplan!$A$2:$A$200,B30&"*",Testplan!$G$2:$G$200,"Pass") -> 0 | E30: =IFERROR(D30/C30,0) -> 0
A31: CDC | B31: CDC | C31: =COUNTIF(Testplan!$A$2:$A$200,B31&"*") -> 1 | D31: =COUNTIFS(Testplan!$A$2:$A$200,B31&"*",Testplan!$G$2:$G$200,"Pass") -> 0 | E31: =IFERROR(D31/C31,0) -> 0
A32: Total | C32: =SUM(C20:C31) -> 44 | D32: =SUM(D20:D31) -> 0 | E32: =IFERROR(D32/C32,0) -> 0

Sheet Components
A1: Component | B1: Role | C1: Where | D1: Status | E1: Notes
A2: Serial pin access (RTL change) | B2: Expose tx as an output and rx as an input on UART and UART_if, with a loopback enable so rx is either tied to tx or driven independently. | C2: UART.sv, UART_if.sv | D2: Not started | E2: Needed for every row that says 'Needs drv_rx', for full-duplex tests, and for decoding tx without hierarchical references. Keep loopback as the default so existing tests still work.
A3: uart_sva.sv (assertions) | B3: SVA checker module attached to UART with bind. Holds the a_* and c_* items named in the Checker and Coverage columns. | C3: uart_sva.sv | D3: Starter written, not simulated | E3: 13 items written (a_rst_values, c_rst_after_traffic, c_rst_mid_tx, a_tx_tick_period, a_tx_idle_high, a_tx_changes_on_tick, a_busy_after_wr_en, c_wr_en_at_busy_fall, c_wr_en_while_busy, a_rdy_holds, a_data_out_with_rdy, c_rdy_clr_collision, c_overrun). Names marked ADD still need writing.
A4: drv_wr (host driver) | B4: Drives rst, wr_en, data_in and rdy_clr with directed and randomised timing (phase relative to tx_tick, back-to-back, held-high, rdy_clr delay). | C4: testbench | D4: Not started
A5: mon_tx (independent TX monitor) | B5: Watches the tx line, measures bit widths in clocks on a grid anchored on the start-bit edge, decodes the byte LSB first, flags aborted frames, checks busy fall against stop-bit start. | C5: testbench | D5: Not started | E5: Must not share code or assumptions with the RTL; that independence is what makes it a real check.
A6: drv_rx (serial RX driver) | B6: Drives the rx line. Knobs: data, bit period in clocks, start-edge phase, stop-bit value, idle gap, glitch width and position, break length. | C6: testbench | D6: Not started | E6: Depends on the serial pin access change.
A7: scb_tx / scb_rx (scoreboards) | B7: Queues of expected bytes compared against mon_tx output and RX data_out at the rdy rise. Flushed on reset. scb_rx must know about dropped, overrun and spurious-byte cases. | C7: testbench | D7: Not started
A8: cov.sv (covergroups) | B8: cg_* / cp_* items named in the Coverage column (data bins, FSM state and transition bins, phase bins, idle gap, glitch width, baud offset, config). | C8: cov.sv | D8: Not started | E8: Name each covergroup exactly as in the plan so a row traces straight to its code.
A9: Regression configs | B9: Parameter sets for PAR001 plus a fast config (e.g. 50 MHz / 312500 baud) for long random runs. | C9: run script | D9: Not started | E9: See Param_Calc for the supported and unsupported combinations.

Sheet Param_Calc
A1: Baud generator parameter check
A2: Mirrors the integer divisions in baud_rate_generator.sv. Edit the blue cells to try other configs.
A3: Mismatch risk threshold | B3: 0.02 | C3: Assumption: the hand estimate of RX baud tolerance is about +/-4 to 5%, so a TX/RX period mismatch above 2% leaves little margin. Not simulated.
A5: clk_freq (Hz) | B5: baud_rate | C5: TX clks/bit | D5: RX tick divisor | E5: RX clks/bit (16x) | F5: TX/RX mismatch | G5: Verdict
A6: 50000000 | B6: 9600 | C6: =INT(A6/B6) -> 5208 | D6: =INT(A6/(B6*16)) -> 325 | E6: =16*D6 -> 5200 | F6: =IF(D6<1,"n/a",(C6-E6)/C6) -> 0.0015360983 | G6: =IF(D6<1,"UNSUPPORTED",IF(D6=1,"EDGE (RX divisor = 1)",IF(ABS(F6)>$B$3,"RISKY","OK"))) -> OK
A7: 50000000 | B7: 115200 | C7: =INT(A7/B7) -> 434 | D7: =INT(A7/(B7*16)) -> 27 | E7: =16*D7 -> 432 | F7: =IF(D7<1,"n/a",(C7-E7)/C7) -> 0.0046082949 | G7: =IF(D7<1,"UNSUPPORTED",IF(D7=1,"EDGE (RX divisor = 1)",IF(ABS(F7)>$B$3,"RISKY","OK"))) -> OK
A8: 50000000 | B8: 312500 | C8: =INT(A8/B8) -> 160 | D8: =INT(A8/(B8*16)) -> 10 | E8: =16*D8 -> 160 | F8: =IF(D8<1,"n/a",(C8-E8)/C8) -> 0 | G8: =IF(D8<1,"UNSUPPORTED",IF(D8=1,"EDGE (RX divisor = 1)",IF(ABS(F8)>$B$3,"RISKY","OK"))) -> OK
A9: 100000000 | B9: 115200 | C9: =INT(A9/B9) -> 868 | D9: =INT(A9/(B9*16)) -> 54 | E9: =16*D9 -> 864 | F9: =IF(D9<1,"n/a",(C9-E9)/C9) -> 0.0046082949 | G9: =IF(D9<1,"UNSUPPORTED",IF(D9=1,"EDGE (RX divisor = 1)",IF(ABS(F9)>$B$3,"RISKY","OK"))) -> OK
A10: 25000000 | B10: 9600 | C10: =INT(A10/B10) -> 2604 | D10: =INT(A10/(B10*16)) -> 162 | E10: =16*D10 -> 2592 | F10: =IF(D10<1,"n/a",(C10-E10)/C10) -> 0.0046082949 | G10: =IF(D10<1,"UNSUPPORTED",IF(D10=1,"EDGE (RX divisor = 1)",IF(ABS(F10)>$B$3,"RISKY","OK"))) -> OK
A11: 50000000 | B11: 921600 | C11: =INT(A11/B11) -> 54 | D11: =INT(A11/(B11*16)) -> 3 | E11: =16*D11 -> 48 | F11: =IF(D11<1,"n/a",(C11-E11)/C11) -> 0.11111111 | G11: =IF(D11<1,"UNSUPPORTED",IF(D11=1,"EDGE (RX divisor = 1)",IF(ABS(F11)>$B$3,"RISKY","OK"))) -> RISKY
A12: 50000000 | B12: 3125000 | C12: =INT(A12/B12) -> 16 | D12: =INT(A12/(B12*16)) -> 1 | E12: =16*D12 -> 16 | F12: =IF(D12<1,"n/a",(C12-E12)/C12) -> 0 | G12: =IF(D12<1,"UNSUPPORTED",IF(D12=1,"EDGE (RX divisor = 1)",IF(ABS(F12)>$B$3,"RISKY","OK"))) -> EDGE (RX divisor = 1)
A13: 50000000 | B13: 6250000 | C13: =INT(A13/B13) -> 8 | D13: =INT(A13/(B13*16)) -> 0 | E13: =16*D13 -> 0 | F13: =IF(D13<1,"n/a",(C13-E13)/C13) -> n/a | G13: =IF(D13<1,"UNSUPPORTED",IF(D13=1,"EDGE (RX divisor = 1)",IF(ABS(F13)>$B$3,"RISKY","OK"))) -> UNSUPPORTED
A15: Default config is row 6 (50 MHz, 9600 baud): TX 5208 clks/bit, RX 325 x 16 = 5200.
A16: RX divisor = 1 is the edge case: $clog2(1) = 0, so the RX counter is declared [-1:0] and the tick fires every clock. Divisor 0 breaks RX.

Sheet Legend
A1: How to use this workbook
A3: Columns (Testplan sheet)
A4: ID | B4: Area prefix + number (RST, BRG, TXF, TXI, RXF, RXI, RXE, BDT, PAR, E2E, FSM, CDC). Summary counts by prefix.
A5: Feature | B5: One checkable statement of what must be true.
A6: Stimulus | B6: What the testbench does to exercise it.
A7: Checker | B7: The mechanism that FAILS if the feature is broken: an assertion, monitor or scoreboard check.
A8: Coverage item | B8: The cover property or covergroup bin that proves the scenario actually happened. A pass without this hit proves nothing.
A9: Priority | B9: P1 = core function, must pass before calling the design verified. P2 = error handling and corner cases. P3 = robustness extras and characterisation.
A10: Status | B10: Not started / In progress / Pass / Fail / Blocked / Waived. Give the reason for any Blocked or Waived in Notes.
A11: What to edit
A12: Yellow cells | B12: Status (Testplan column G and Components column D) and the blue input cells on Param_Calc. Everything else can stay as is; add rows below the last one and the Summary picks them up (formulas read down to row 200).
A13: Example row | B13: Read RST001 as: after reset the outputs have their reset values (feature); hold rst, then re-apply it after a frame (stimulus); assertion a_rst_values fails if not (checker); c_rst_after_traffic proves the second case ran (coverage); P1; Not started.
A14: Naming convention
A15: a_* / c_* | B15: SVA assert / cover directives. These live in uart_sva.sv. Where a row lists '(vacuity)', the cover is the assertion's antecedent, to catch an assertion that never triggered.
A16: (ADD SVA) / ADD | B16: Named in the plan but not yet written in uart_sva.sv. The Summary counts the Checker cells containing 'ADD SVA'.
A17: mon_tx, drv_rx, drv_wr, scb_* | B17: Testbench components, described on the Components sheet.
A18: cg_* / cp_* | B18: Covergroups and coverpoints in cov.sv.
A19: Assumptions and sources
A20: RTL read | B20: baud_rate_generator.sv, transmitter_block.sv, receiver_block.sv, UART.sv and UART_if.sv from the UART folder of Ah-deee/sv_labs, as read during this conversation. uart_pkg.sv and cov.sv were empty.
A21: Default numbers | B21: clk_freq = 50,000,000 and baud_rate = 9600 are the defaults in baud_rate_generator.sv. They give 5208 TX clocks per bit and an rx_tick every 325 clocks (16 x 325 = 5200).
A22: Baud tolerance | B22: The +/-4 to 5% figure is a hand calculation (stop bit sampled 9.5 bit times after the start edge, start detection up to 1/16 bit late). It has not been simulated.
A23: Glitch threshold | B23: The 'about half a bit' figure comes from the 8-rx_tick start-bit check (8 x 325 = 2600 clocks of a 5200-clock bit). Not simulated.
A24: Not simulated | B24: Nothing in this plan has been run. Timing bounds in the assertions (for example the +1 slack in a_start_latency) may need adjusting after the first run.
A25: Design limitations | B25: No framing-error, overrun or break flags exist; those cases are dropped silently. The plan lists them so the spec can state it explicitly.
